<robot name="pioneer">
	<!-- Base link to interface with gmapping and move_base -->
  <link name="base_link"/>

  <!-- Chassis -->
  <joint name="chassis_joint" type="fixed">
    <origin xyz="-0.045 0 0.148" rpy="0 0 0"/>
    <parent link="base_link"/>
    <child link="chassis"/>
  </joint>

  <link name="chassis">
    <visual name="chassis_visual">
      <origin xyz="0 0 0" rpy="0 0 0"/>
      <geometry name="pioneer_geom">
      <mesh filename="package://labrob_description/meshes/p3dx_meshes/chassis.stl"/>
      </geometry>
      <material name="ChassisRed"/>
    </visual>
    <collision>
			<origin xyz="0 0 0" rpy="0 0 0"/>
			<geometry>
				<mesh filename="package://labrob_description/meshes/p3dx_meshes/chassis.stl"/>
				<!--box size="0.43 0.277 0.17"/-->
			</geometry>
		</collision>
		<inertial>
			<mass value="5.67"/>
			<inertia ixx="0.07" ixy="0" ixz="0" iyy="0.08" iyz="0" izz="0.10"/>
		</inertial>
  </link>

<!-- Top -->
    <joint name="base_top_joint" type="fixed">
        <origin xyz="-0.045 0 0.234" rpy="0 0 0"/>
        <parent link="base_link"/>
        <child link="top_plate"/>
    </joint>

    <link name="top_plate">
        <visual>
            <inertial>
                <mass value="0.01"/>    
                <origin xyz="0 0 0"/>
                <inertia ixx="1" ixy="0" ixz="0"
                     iyy="1" iyz="0"
                    izz="1"/>
            </inertial>
            <origin xyz="0 0 0" rpy="0 0 0"/>
            <geometry name="top_geom">
                <mesh filename="package://labrob_description/meshes/p3dx_meshes/top.stl"/>
            </geometry>
            <material name="TopBlack"/>
        </visual>
        <collision>
            <origin xyz="0 0 0" rpy="0 0 0"/>
            <geometry>
                <mesh filename="package://labrob_description/meshes/p3dx_meshes/top.stl"/>
                <!--box size="0.44 0.38 0.005"/-->
            </geometry>
        </collision>
    </link>

<!-- Swivel -->
    <joint name="base_swivel_joint" type="continuous">
        <origin xyz="-0.185 0 0.055" rpy="0 0 0"/>
        <axis xyz="0 0 1"/>
        <!--<anchor xyz="0 0 0"/>
    <limit effort="100" velocity="100" k_velocity="0" />
    <joint_properties damping="0.0" friction="0.0" />-->
        <parent link="base_link"/>
        <child link="swivel"/>
    </joint>
    
    <link name="swivel">
        <inertial>
            <mass value="0.1"/> 
            <origin xyz="0 0 0"/>
            <inertia ixx="0.01" ixy="0" ixz="0"
                 iyy="0.01" iyz="0" izz="0.01"/>
    </inertial>
      <visual name="base_visual">
          <origin xyz="0 0 0" rpy="0 0 0"/>
          <geometry name="pioneer_geom">
              <mesh filename="package://labrob_description/meshes/p3dx_meshes/swivel.stl"/>
          </geometry>
          <material name="swivel"/>
      </visual>
      <collision>
          <origin xyz="0 0 0" rpy="0 0 0"/>
          <geometry>
              <mesh filename="package://labrob_description/meshes/p3dx_meshes/swivel.stl"/>
          </geometry>
      </collision>
    </link>

<!-- Center Wheel + Hubcap -->
    <link name="center_hubcap">
        <inertial>
            <mass value="0.01"/>    
            <origin xyz="0 0 0"/>
            <inertia ixx="0.012411765597" ixy="-0.000711733678" ixz="0.00050272983"
                 iyy="0.015218160428" iyz="-0.000004273467" izz="0.011763977943"/>
        </inertial>
      <visual name="base_visual">
          <origin xyz="0 0 0" rpy="0 0 0"/>
          <geometry name="pioneer_geom">
              <mesh filename="package://labrob_description/meshes/p3dx_meshes/center_hubcap.stl"/>
          </geometry>
          <material name="HubcapGrey"/>
      </visual>
      <collision>
          <origin xyz="0 0 0" rpy="0 0 0"/>
          <geometry>
              <mesh filename="package://labrob_description/meshes/p3dx_meshes/center_hubcap.stl"/>
          </geometry>
      </collision>
    </link>

    <joint name="swivel_hubcap_joint" type="continuous">
        <origin xyz="-0.026 0 -0.016" rpy="0 0 0"/>
        <axis xyz="0 1 0"/>
        <!--<anchor xyz="0 0 0"/>
    <limit effort="1000" velocity="1000" k_velocity="0" />
    <joint_properties damping="0.0" friction="0.0" />-->
      <parent link="swivel"/>
        <child link="center_wheel"/>
    </joint>

    <link name="center_wheel">
        <inertial>
            <mass value="0.1"/> 
            <origin xyz="0 0 0"/>
            <inertia ixx="0.012411765597" ixy="-0.000711733678" ixz="0.00050272983"
                 iyy="0.015218160428" iyz="-0.000004273467" izz="0.011763977943"/>
        </inertial>
      <visual name="base_visual">
          <origin xyz="0 0 0" rpy="0 0 0"/>
          <geometry name="pioneer_geom">
              <mesh filename="package://labrob_description/meshes/p3dx_meshes/center_wheel.stl"/>
          </geometry>
          <material name="WheelBlack"/>
      </visual>
      <collision>
          <origin xyz="0 0 0" rpy="0 0 0"/>
          <geometry>
            <mesh filename="package://labrob_description/meshes/p3dx_meshes/center_wheel.stl"/>
              <!--<cylinder radius="0.0375" length="0.03"/>-->
          </geometry>
      </collision>
    </link>

    <joint name="center_wheel_joint" type="fixed">
        <origin xyz="-0.0035 0 -0.001" rpy="0 0 0"/>
        <parent link="center_wheel"/>
        <child link="center_hubcap"/>
    </joint>
    
    <!-- Left Wheel -->
    <joint name="base_left_wheel_joint" type="continuous">
        <origin xyz="0 0.155 0.093" rpy="0 0 0"/>
        <axis xyz="0 1 0"/>
        <!--<anchor xyz="0 0 0"/>
    <limit effort="1000" velocity="1000" k_velocity="0" />
    <joint_properties damping="0.0" friction="0.0" />-->
        <parent link="base_link"/>
        <child link="left_wheel"/>
    </joint>

    <link name="left_wheel">
      <inertial>
            <mass value="0.1"/> 
            <origin xyz="0 0 0"/>
          <inertia ixx="0.012411765597" ixy="-0.000711733678" ixz="0.00050272983"
                 iyy="0.015218160428" iyz="-0.000004273467" izz="0.011763977943"/>
    </inertial>
        <visual>
            <origin xyz="0 0 0" rpy="0 0 0"/>
            <geometry>
                <mesh filename="package://labrob_description/meshes/p3dx_meshes/left_wheel.stl"/>
            </geometry>
            <material name="WheelBlack"/>
        </visual>
        <collision>
            <origin xyz="0 0 0" rpy="0 0 0"/>
            <geometry>
              <mesh filename="package://labrob_description/meshes/p3dx_meshes/left_wheel.stl"/>
                <!--<cylinder radius="0.092" length="0.04"/>-->
            </geometry>
        </collision>
    </link>

    <joint name="left_wheel_hub_joint" type="fixed">
        <origin xyz="0 0 0" rpy="0 0 0"/>
        <parent link="left_wheel"/>
        <child link="left_hub"/>
    </joint>

    <link name="left_hub">
        <visual>
            <origin xyz="0 0 0" rpy="0 0 0"/>
            <geometry>
                <mesh filename="package://labrob_description/meshes/p3dx_meshes/left_hubcap.stl"/>
            </geometry>
            <material name="HubcapYellow"/>
        </visual>
        <collision>
            <origin xyz="0 0 0" rpy="0 0 0"/>
            <geometry>
                <mesh filename="package://labrob_description/meshes/p3dx_meshes/left_hubcap.stl"/>
            </geometry>
        </collision>
    </link>
    
    <!-- Right Wheel -->
    <joint name="base_right_wheel_joint" type="continuous">
        <origin xyz="0 -0.155 0.093" rpy="0 0 0"/>
        <axis xyz="0 1 0"/>
        <!--<anchor xyz="0 0 0"/>
    <limit effort="1000" velocity="1000" k_velocity="0" />
    <joint_properties damping="0.0" friction="0.0" />-->
        <parent link="base_link"/>
        <child link="right_wheel"/>
    </joint>

    <link name="right_wheel">
    <inertial>
            <mass value="0.1"/> 
            <origin xyz="0 0 0"/>
            <inertia ixx="0.012411765597" ixy="-0.000711733678" ixz="0.00050272983"
                 iyy="0.015218160428" iyz="-0.000004273467" izz="0.011763977943"/>
    </inertial>
        <visual>
            <origin xyz="0 0 0" rpy="0 0 0"/>
            <geometry>
                <mesh filename="package://labrob_description/meshes/p3dx_meshes/right_wheel.stl"/>
            </geometry>
            <material name="WheelBlack"/>
        </visual>
        <collision>
            <origin xyz="0 0 0" rpy="0 0 0"/>
            <geometry>
              <mesh filename="package://labrob_description/meshes/p3dx_meshes/right_wheel.stl"/>
                <!--<cylinder radius="0.092" length="0.04"/>-->
            </geometry>
        </collision>
    </link>

    <joint name="right_wheel_hub_joint" type="fixed">
        <origin xyz="0 0 0" rpy="0 0 0"/>
        <parent link="right_wheel"/>
        <child link="right_hub"/>
    </joint>

    <link name="right_hub">
        <visual>
            <origin xyz="0 0 0" rpy="0 0 0"/>
            <geometry>
                <mesh filename="package://labrob_description/meshes/p3dx_meshes/right_hubcap.stl"/>
            </geometry>
            <material name="HubcapYellow"/>
        </visual>
        <collision>
            <origin xyz="0 0 0" rpy="0 0 0"/>
            <geometry>
                <mesh filename="package://labrob_description/meshes/p3dx_meshes/right_hubcap.stl"/>
            </geometry>
        </collision>
    </link>

<!-- Front + Back Sonar -->
    <link name="front_sonar">
        <inertial>
            <mass value="0.0001"/>  
            <origin xyz="0 0 0"/>
            <inertia ixx="1" ixy="0" ixz="0"
                 iyy="1" iyz="0" izz="1"/>
        </inertial>
        <visual name="base_visual">
            <origin xyz="0 0 0" rpy="0 0 0"/>
            <geometry name="pioneer_geom">
                <mesh filename="package://labrob_description/meshes/p3dx_meshes/front_sonar.stl"/>
            </geometry>
            <material name="SonarYellow"/>
        </visual>
        <collision>
            <origin xyz="0 0 0" rpy="0 0 0"/>
            <geometry>
                <mesh filename="package://labrob_description/meshes/p3dx_meshes/front_sonar.stl"/>
            </geometry>
        </collision>
    </link>

    <joint name="base_front_joint" type="fixed">
        <origin xyz="-0.198 0 0.208" rpy="0 0 0"/>
        <parent link="base_link"/>
        <child link="front_sonar"/>
    </joint>

    <link name="back_sonar">
        <inertial>
            <mass value="0.0001"/>  
            <origin xyz="0 0 0"/>
            <inertia ixx="1" ixy="0" ixz="0"
                 iyy="1" iyz="0" izz="1"/>
        </inertial>
        <visual name="back_sonar_vis">
            <origin xyz="0 0 0" rpy="0 0 0"/>
            <geometry name="pioneer_geom">
                <mesh filename="package://labrob_description/meshes/p3dx_meshes/back_sonar.stl"/>
            </geometry>
            <material name="SonarYellow"/>
        </visual>
        <collision>
            <origin xyz="0 0 0" rpy="0 0 0"/>
            <geometry>
                <mesh filename="package://labrob_description/meshes/p3dx_meshes/back_sonar.stl"/>
            </geometry>
        </collision>
    </link>

    <joint name="base_back_joint" type="fixed">
        <origin xyz="0.109 0 0.209" rpy="0 0 0"/>
        <parent link="base_link"/>
        <child link="back_sonar"/>
    </joint>

    <!-- Kinect -->
    <sensor_kinect  parent="top_plate"/>

    <!-- Cyton Gamma --> 

    <joint name="cyton_base_joint" type="fixed">
      <origin xyz="0 0 0" rpy="0 0 0"/>
      <parent link="top_plate"/>
      <child link="cyton_base_link" />
    </joint>

    <link name="cyton_base_link">
      <visual>
        <origin xyz="0 0 0" rpy="0 0 0"/>
        <geometry>
          <mesh filename="package://labrob_description/meshes/cyton/base.dae"/>
        </geometry>
      </visual>
      <collision>
        <origin xyz="0 0.0115 0.047"/>
        <geometry>
          <!--mesh filename="package://labrob_description/meshes/cyton/base.dae"/-->
          <box size="0.154 0.177 0.094"/>
        </geometry>
      </collision>
      <inertial>
        <mass value="0.1"/>
        <origin rpy="0 0 0" xyz="0 0 0"/>
        <inertia ixx="0.0025" iyy="0.0025" izz="0.0025"
                  ixy="0" ixz="0" iyz="0"/>
      </inertial>
    </link>

    <joint name="shoulder_roll_joint" type="revolute">
      <parent link="cyton_base_link" />
      <child link="shoulder_roll" />
      <origin xyz="0 0 0.05315" rpy="0 0 0" />
      <limit lower="-2.618" upper="2.618" effort="100.0" velocity="1.0" />
      <axis xyz="0 0 1" />
    </joint>

    <link name="shoulder_roll">
      <visual>
        <origin xyz="0 0 0" rpy="1.5708 0 0.384"/>
        <geometry>
          <mesh filename="package://labrob_description/meshes/cyton/shoulder_roll.dae"/>
        </geometry>
      </visual>
      <collision>
        <origin xyz="0.0 0.069 0.0587"/>
        <geometry>
          <!--mesh filename="package://labrob_description/meshes/cyton/shoulder_roll.dae"/-->
          <box size="0.09829 0.18143 0.08392"/>
        </geometry>
      </collision>
     <inertial>
        <mass value="0.05"/>
        <origin rpy="0 0 0" xyz="0 0 0"/>
        <inertia ixx="0.0012" iyy="0.0012" izz="0.0012"
                  ixy="0" ixz="0" iyz="0"/>
      </inertial>
    </link>

    <joint name="shoulder_pitch_joint" type="revolute">
      <parent link="shoulder_roll" />
      <child link="shoulder_pitch" />
      <origin xyz="0.0205 0 0.12435" rpy="0 0 0" />
      <limit lower="-1.8326" upper="1.8326" effort="100.0" velocity="1.0" />
      <axis xyz="1 0 0" />
    </joint>

    <link name="shoulder_pitch">
      <visual>
        <origin xyz="0 0 0" rpy="1.5708 0 0" />
        <geometry>
          <mesh filename="package://labrob_description/meshes/cyton/shoulder_pitch.dae"/>
        </geometry>
      </visual>
      <collision>
        <origin xyz="-0.001 0.064 0.1745"/>
        <geometry>
          <!--mesh filename="package://labrob_description/meshes/cyton/shoulder_pitch.dae"/-->
          <box size="0.0709 0.19363 0.083"/>
        </geometry>
      </collision>
     <inertial>
        <mass value="0.02"/>
        <origin rpy="0 0 0" xyz="0 0 0"/>
        <inertia ixx="0.00024" iyy="0.00024" izz="0.00024"
                  ixy="0" ixz="0" iyz="0"/>
      </inertial>
    </link>

    <joint name="shoulder_yaw_joint" type="revolute">
      <parent link="shoulder_pitch" />
      <child link="shoulder_yaw" />
      <origin xyz="-0.0215 -0.0205 0.1255" rpy="0 0 0" />
      <limit lower="-1.8326" upper="1.8326" effort="100.0" velocity="1.0" />
      <axis xyz="0 -1 0" />
    </joint>

    <link name="shoulder_yaw">
      <visual>
        <origin xyz="0 0 0.0" rpy="1.5708 0 -1.5708" />
        <geometry>
          <mesh filename="package://labrob_description/meshes/cyton/shoulder_yaw.dae"/>
        </geometry>
      </visual>
      <collision>
        <origin xyz="-0.0225 0.039 0.3068"/>
        <geometry>
      	  <!--mesh filename="package://labrob_description/meshes/cyton/shoulder_yaw.dae"/-->
          <box size="0.0717 0.1846 0.0756"/>
        </geometry>
      </collision>
      <inertial>
        <mass value="0.01"/>
        <origin rpy="0 0 0" xyz="0 0 0"/>
        <inertia ixx="0.00012" iyy="0.00012" izz="0.00012"
                  ixy="0" ixz="0" iyz="0"/>
      </inertial>
    </link>

    <joint name="elbow_pitch_joint" type="revolute">
      <parent link="shoulder_yaw" />
      <child link="elbow_pitch" />
      <origin xyz="0.018 0.0206 0.1158" rpy="0 0 0" />
      <limit lower="-1.8326" upper="1.8326" effort="100.0" velocity="1.0" />
      <axis xyz="1 0 0" />
    </joint>

    <link name="elbow_pitch">
      <visual>
        <origin xyz="0 0 0" rpy="1.5708 0 3.1416" />
        <geometry>
          <mesh filename="package://labrob_description/meshes/cyton/elbow_pitch.dae"/>
        </geometry>
      </visual>
      <collision>
        <origin xyz="0.0346 0.0461 0.4228"/>
        <geometry>
	        <!--mesh filename="package://labrob_description/meshes/cyton/elbow_pitch.dae"/-->
          <box size="0.0549 0.1557 0.076"/>
        </geometry>
      </collision>
      <inertial>
        <mass value="0.01"/>
        <origin rpy="0 0 0" xyz="0 0 0"/>
        <inertia ixx="0.00012" iyy="0.00012" izz="0.00012"
                  ixy="0" ixz="0" iyz="0"/>
      </inertial>
    </link>

    <joint name="elbow_yaw_joint" type="revolute">
      <parent link="elbow_pitch" />
      <child link="elbow_yaw" />
      <origin xyz="-0.0171 -0.018 0.09746" rpy="0 0 0" />
      <limit lower="-1.8326" upper="1.8326" effort="100.0" velocity="1.0" />
      <axis xyz="0 -1 0" />
    </joint>

    <link name="elbow_yaw">
      <visual>
        <origin xyz="0 0 0" rpy="1.5708 0 1.5708" />
        <geometry>
          <mesh filename="package://labrob_description/meshes/cyton/elbow_yaw.dae"/>
        </geometry>
      </visual>
      <collision>
        <origin xyz="0.0172 0.0209 0.516"/>
        <geometry>
          <!--mesh filename="package://labrob_description/meshes/cyton/elbow_yaw.dae"/-->
          <box size="0.0535 0.1160 0.0402"/>
        </geometry>
      </collision>
      <inertial>
        <mass value="0.01"/>
        <origin rpy="0 0 0" xyz="0 0 0"/>
        <inertia ixx="0.00012" iyy="0.00012" izz="0.00012"
                  ixy="0" ixz="0" iyz="0"/>
      </inertial>
    </link>

    <joint name="wrist_pitch_joint" type="revolute">
      <parent link="elbow_yaw" />
      <child link="wrist_pitch" />
      <origin xyz="0.02626 0.018 0.0718" rpy="0 0 0" />
      <limit lower="-1.8326" upper="1.8326" effort="100.0" velocity="1.0" />
      <axis xyz="1 0 0" />
    </joint>

    <link name="wrist_pitch">
      <visual>
        <origin xyz="0 0 0" rpy="1.5708 0 1.5708" />
        <geometry>
          <mesh filename="package://labrob_description/meshes/cyton/wrist_pitch.dae"/>
        </geometry>
      </visual>
      <collision>
        <origin xyz="0.0257 0.0118 0.5617"/>
        <geometry>
          <!--mesh filename="package://labrob_description/meshes/cyton/wrist_pitch.dae"/-->
          <box size="0.026 0.0435 0.05185"/>
        </geometry>
      </collision>
      <inertial>
        <mass value="0.01"/>
        <origin rpy="0 0 0" xyz="0 0 0"/>
        <inertia ixx="0.00012" iyy="0.00012" izz="0.00012"
                  ixy="0" ixz="0" iyz="0"/>
      </inertial>
    </link>

    <joint name="wrist_roll_joint" type="revolute">
      <parent link="wrist_pitch" />
      <child link="wrist_roll" />
      <origin xyz="-0.026255 0 0.051425" rpy="0 0 0" />
      <limit lower="-2.61799" upper="2.61799" effort="100.0" velocity="1.0" />
      <axis xyz="0 0 1" />
    </joint>

    <link name="wrist_roll">
      <visual>
        <origin xyz="0 0 0" rpy="3.1416 0 -1.5708" />
        <geometry>
          <mesh filename="package://labrob_description/meshes/cyton/wrist_roll.dae"/>
        </geometry>
      </visual>
      <collision>
        <origin xyz="-0.0063 -0.0014 0.6102"/>
        <geometry>
          <!--mesh filename="package://labrob_description/meshes/cyton/wrist_roll.dae"/-->
          <box size="0.0518 0.0723 0.1004"/>
        </geometry>
      </collision>
      <inertial>
        <mass value="0.01"/>
        <origin rpy="0 0 0" xyz="0 0 0"/>
        <inertia ixx="0.00012" iyy="0.00012" izz="0.00012"
                  ixy="0" ixz="0" iyz="0"/>
      </inertial>
    </link>

    <joint name="gripper_joint1" type="prismatic">
      <parent link="wrist_roll" />
      <child link="gripper_finger1" />
      <origin xyz="-0.01331 0.00485 0.077225" rpy="0 0 0" />
      <limit lower="-0.008" upper="0.008" effort="100.0" velocity="1.0" />
      <axis xyz="1 0 0" />
    </joint>

    <link name="gripper_finger1">
      <visual>
        <origin xyz="0 0 0" rpy="0 0 0" />
        <geometry>
          <mesh filename="package://labrob_description/meshes/cyton/gripper_finger1.dae"/>
        </geometry>
      </visual>
      <collision>
        <origin xyz="-0.0167 0.0172 0.7254"/>
        <geometry>
          <!--mesh filename="package://labrob_description/meshes/cyton/gripper_finger1.dae"/-->
          <box size="0.015 0.0229 0.0475"/>
        </geometry>
      </collision>
      <inertial>
        <mass value="0.001"/>
        <origin rpy="0 0 0" xyz="0 0 0"/>
        <inertia ixx="0.0001" iyy="0.0001" izz="0.0001"
                  ixy="0" ixz="0" iyz="0"/>
      </inertial>
    </link>

    <joint name="gripper_joint2" type="prismatic">
      <parent link="wrist_roll" />
      <child link="gripper_finger2" />
      <origin xyz="0.0098 0.00485 0.077225" rpy="0 0 0" />
      <limit lower="-0.008" upper="0.008" effort="100.0" velocity="1.0" />
      <mimic joint="gripper_joint1" multiplier="-1"/>
      <axis xyz="1 0 0" />
    </joint>

    <link name="gripper_finger2">
      <visual>
        <origin xyz="0 0 0" rpy="0 0 0" />
        <geometry>
          <mesh filename="package://labrob_description/meshes/cyton/gripper_finger2.dae"/>
        </geometry>
      </visual>
      <collision>
        <origin xyz="0.0132 0.0172 0.7254"/>
        <geometry>
          <!--mesh filename="package://labrob_description/meshes/cyton/gripper_finger2.dae"/-->
          <box size="0.015 0.0229 0.0475"/>
        </geometry>
      </collision>
      <inertial>
        <mass value="0.001"/>
        <origin rpy="0 0 0" xyz="0 0 0"/>
        <inertia ixx="0.0001" iyy="0.0001" izz="0.0001"
                  ixy="0" ixz="0" iyz="0"/>
      </inertial>
    </link>
    
    
    <!--  virtual gripper  stuff  --> 

    <joint name="virtual_endeffector_joint" type="fixed">
      <parent link="wrist_roll"/>
      <child link="virtual_endeffector"/>
      <origin rpy="0 0 0" xyz="-0.002316 0.0079 0.079425"/>
    </joint>

    <link name="virtual_endeffector">
      <visual>
        <origin rpy="0 0 0" xyz="0 0 0"/>
        <geometry>
          <sphere radius="0.002"/>
        </geometry>
        <material name="grey">
          <color rgba="0.7 0.7 0.7 0.8"/>
        </material>
      </visual>
    </link> 

</robot>